Workbook
Name esp_json: #REF!
Name esp_json_1: Unifloc!$B$13
Name feed_json: Unifloc!$H$15
Name PumpIds: Pumps!$A$2:$A$57
Name PVT_json: Unifloc!$H$10

Sheet README
A1: Excel-проверка расчета ЭЦН по диаграммам Сютера
A3: Как пользоваться
A4: 1. Откройте лист 'Проверка'.
A5: 2. В ячейке B2 выберите ID ЭЦН из выпадающего списка.
A6: 3. Проверьте базовые величины Q*, H*, N*, nq и ближайшую группу Сютера.
A7: 4. В таблице ниже Excel формулами пересчитывает v, theta, Wh/Wm, H_suter, N_suter и КПД.
A8: 5. Листы Pumps, CatalogData и SuterWide оставлены видимыми, чтобы можно было проверить исходные данные.
A11: Принятые ограничения
A12: alpha = 1; отрицательная частота вращения в этой проверке не моделируется.
A13: Мощность обозначается N, чтобы не путать ее с давлением P.

Sheet Проверка
A1: Проверка расчета ЭЦН по диаграммам Сютера
A2: ID ЭЦН | B2: 750
A3: Название | B3: =IFERROR(INDEX(Pumps!$B:$B,MATCH($B$2,Pumps!$A:$A,0)),"") -> ЭЦН5А-280 | D3: Ключевые формулы
A4: Производитель | B4: =IFERROR(INDEX(Pumps!$C:$C,MATCH($B$2,Pumps!$A:$A,0)),"") -> Generic | D4: v = Q / Q*
A5: Серия | B5: =IFERROR(INDEX(Pumps!$D:$D,MATCH($B$2,Pumps!$A:$A,0)),"") -> 5А | D5: theta = DEGREES(ATAN2(v, alpha))
A6: Q*, м3/сут | B6: =IFERROR(INDEX(Pumps!$E:$E,MATCH($B$2,Pumps!$A:$A,0)),"") -> 280 | D6: Wh = (H/H*)/(alpha^2+v^2)
A7: H*, м | B7: =IFERROR(INDEX(Pumps!$F:$F,MATCH($B$2,Pumps!$A:$A,0)),"") -> 5.63 | D7: H_suter = Wh(theta)*(alpha^2+v^2)*H*
A8: N*, кВт | B8: =IFERROR(INDEX(Pumps!$G:$G,MATCH($B$2,Pumps!$A:$A,0)),"") -> 0.408 | D8: N_suter = Wm(theta)*(alpha^2+v^2)*N*
A9: freq, Hz | B9: =IFERROR(INDEX(Pumps!$H:$H,MATCH($B$2,Pumps!$A:$A,0)),"") -> 50 | D9: eta_signed = rho*g*(Q/86400)*H_suter/(N_suter*1000)
A10: n = freq*60, rpm | B10: =IFERROR($B$9*60,"") -> 3000 | D10: Wh(theta), Wm(theta) интерполируются по ближайшей группе Сютера.
A11: nq SI | B11: =IFERROR($B$10*SQRT($B$6/86400)/($B$7^0.75),"") -> 46.726376
A12: Ближайшая группа Сютера | B12: =IF($B$11="","",IF(ABS($B$11-25)<=MIN(ABS($B$11-147),ABS($B$11-261)),25,IF(ABS($B$11-147)<=ABS($B$11-261),147,261))) -> 25
A13: Ns field | B13: =IFERROR($B$10*SQRT($B$6*264.172052/1440)/(($B$7*3.280839895)^0.75),"") -> 2413.1948
A14: alpha | B14: 1
A15: rho, кг/м3 | B15: 1000
A16: g, м/с2 | B16: 9.80665
A17: slip_nom_rpm (справочно) | B17: =IFERROR(INDEX(Pumps!$I:$I,MATCH($B$2,Pumps!$A:$A,0)),"") -> 2910
A21: n | B21: строка данных | C21: Q_db, м3/сут | D21: H_db, м | E21: N_db, кВт | F21: eta_db | G21: v | H21: theta, град | I21: Wh_db | J21: Wm_db | K21: idx theta | L21: theta_lo | M21: theta_hi | N21: Wh_lo | O21: Wh_hi | P21: Wh_suter | Q21: Wm_lo | R21: Wm_hi | S21: Wm_suter | T21: H_suter, м | U21: Delta H, м | V21: N_suter, кВт | W21: Delta N, кВт | X21: eta_signed | Y21: eta_abs | Z21: Delta eta
A22: 1 | B22: =IFERROR(MATCH($B$2&"|"&A22,CatalogData!$G:$G,0),"") -> 307 | C22: =IF($B22="","",INDEX(CatalogData!$C:$C,$B22)) -> 0 | D22: =IF($B22="","",INDEX(CatalogData!$D:$D,$B22)) -> 6.75 | E22: =IF($B22="","",INDEX(CatalogData!$E:$E,$B22)) -> 0.199 | F22: =IF($B22="","",INDEX(CatalogData!$F:$F,$B22)) -> 0.01 | G22: =IF($B22="","",IFERROR($C22/$B$6,"")) -> 0 | H22: =IF($B22="","",IFERROR(DEGREES(ATAN2($G22,$B$14)),"")) -> 90 | I22: =IF($B22="","",IFERROR(($D22/$B$7)/($B$14^2+$G22^2),"")) -> 1.1989343 | J22: =IF($B22="","",IFERROR(($E22/$B$8)/($B$14^2+$G22^2),"")) -> 0.4877451 | K22: =IF($B22="","",IFERROR(MATCH($H22,SuterWide!$A$2:$A$56,1),"")) -> 19 | L22: =IF($K22="","",INDEX(SuterWide!$A$2:$A$56,$K22)) -> 90 | M22: =IF($K22="","",INDEX(SuterWide!$A$2:$A$56,MIN($K22+1,ROWS(SuterWide!$A$2:$A$56)))) -> 95 | N22: =IF($K22="","",IF($B$12=25,INDEX(SuterWide!$B$2:$B$56,$K22),IF($B$12=147,INDEX(SuterWide!$D$2:$D$56,$K22),INDEX(SuterWide!$F$2:$F$56,$K22)))) -> 1.29 | O22: =IF($K22="","",IF($B$12=25,INDEX(SuterWide!$B$2:$B$56,MIN($K22+1,ROWS(SuterWide!$A$2:$A$56))),IF($B$12=147,INDEX(SuterWide!$D$2:$D$56,MIN($K22+1,ROWS(SuterWide!$A$2:$A$56))),INDEX(SuterWide!$F$2:$F$56,MIN($K22+1,ROWS(SuterWide!$A$2:$A$56)))))) -> 1.287 | P22: =IF($K22="","",IF($M22=$L22,$N22,$N22+($H22-$L22)/($M22-$L22)*($O22-$N22))) -> 1.29 | Q22: =IF($K22="","",IF($B$12=25,INDEX(SuterWide!$C$2:$C$56,$K22),IF($B$12=147,INDEX(SuterWide!$E$2:$E$56,$K22),INDEX(SuterWide!$G$2:$G$56,$K22)))) -> 0.44 | R22: =IF($K22="","",IF($B$12=25,INDEX(SuterWide!$C$2:$C$56,MIN($K22+1,ROWS(SuterWide!$A$2:$A$56))),IF($B$12=147,INDEX(SuterWide!$E$2:$E$56,MIN($K22+1,ROWS(SuterWide!$A$2:$A$56))),INDEX(SuterWide!$G$2:$G$56,MIN($K22+1,ROWS(SuterWide!$A$2:$A$56)))))) -> 0.402 | S22: =IF($K22="","",IF($M22=$L22,$Q22,$Q22+($H22-$L22)/($M22-$L22)*($R22-$Q22))) -> 0.44 | T22: =IF($P22="","",$P22*($B$14^2+$G22^2)*$B$7) -> 7.2627 | U22: =IF($T22="","",$T22-$D22) -> 0.5127 | V22: =IF($S22="","",$S22*($B$14^2+$G22^2)*$B$8) -> 0.17952 | W22: =IF($V22="","",$V22-$E22) -> -0.01948 | X22: =IF($B22="","",IFERROR(IF(OR($V22="",ABS($V22)<0.000000001),"",$B$15*$B$16*($C22/86400)*$T22/($V22*1000)),"")) -> 0 | Y22: =IF($B22="","",IFERROR(ABS($X22),"")) -> 0 | Z22: =IF($B22="","",IFERROR(IF(OR($F22="",$X22=""),"",$X22-$F22),"")) -> -0.01
A23: 2 | B23: =IFERROR(MATCH($B$2&"|"&A23,CatalogData!$G:$G,0),"") -> 308 | C23: =IF($B23="","",INDEX(CatalogData!$C:$C,$B23)) -> 40 | D23: =IF($B23="","",INDEX(CatalogData!$D:$D,$B23)) -> 6.4 | E23: =IF($B23="","",INDEX(CatalogData!$E:$E,$B23)) -> 0.229 | F23: =IF($B23="","",INDEX(CatalogData!$F:$F,$B23)) -> 0.11 | G23: =IF($B23="","",IFERROR($C23/$B$6,"")) -> 0.14285714 | H23: =IF($B23="","",IFERROR(DEGREES(ATAN2($G23,$B$14)),"")) -> 81.869898 | I23: =IF($B23="","",IFERROR(($D23/$B$7)/($B$14^2+$G23^2),"")) -> 1.114032 | J23: =IF($B23="","",IFERROR(($E23/$B$8)/($B$14^2+$G23^2),"")) -> 0.55004902 | K23: =IF($B23="","",IFERROR(MATCH($H23,SuterWide!$A$2:$A$56,1),"")) -> 17 | L23: =IF($K23="","",INDEX(SuterWide!$A$2:$A$56,$K23)) -> 80 | M23: =IF($K23="","",INDEX(SuterWide!$A$2:$A$56,MIN($K23+1,ROWS(SuterWide!$A$2:$A$56)))) -> 85 | N23: =IF($K23="","",IF($B$12=25,INDEX(SuterWide!$B$2:$B$56,$K23),IF($B$12=147,INDEX(SuterWide!$D$2:$D$56,$K23),INDEX(SuterWide!$F$2:$F$56,$K23)))) -> 1.245 | O23: =IF($K23="","",IF($B$12=25,INDEX(SuterWide!$B$2:$B$56,MIN($K23+1,ROWS(SuterWide!$A$2:$A$56))),IF($B$12=147,INDEX(SuterWide!$D$2:$D$56,MIN($K23+1,ROWS(SuterWide!$A$2:$A$56))),INDEX(SuterWide!$F$2:$F$56,MIN($K23+1,ROWS(SuterWide!$A$2:$A$56)))))) -> 1.278 | P23: =IF($K23="","",IF($M23=$L23,$N23,$N23+($H23-$L23)/($M23-$L23)*($O23-$N23))) -> 1.2573413 | Q23: =IF($K23="","",IF($B$12=25,INDEX(SuterWide!$C$2:$C$56,$K23),IF($B$12=147,INDEX(SuterWide!$E$2:$E$56,$K23),INDEX(SuterWide!$G$2:$G$56,$K23)))) -> 0.53 | R23: =IF($K23="","",IF($B$12=25,INDEX(SuterWide!$C$2:$C$56,MIN($K23+1,ROWS(SuterWide!$A$2:$A$56))),IF($B$12=147,INDEX(SuterWide!$E$2:$E$56,MIN($K23+1,ROWS(SuterWide!$A$2:$A$56))),INDEX(SuterWide!$G$2:$G$56,MIN($K23+1,ROWS(SuterWide!$A$2:$A$56)))))) -> 0.479 | S23: =IF($K23="","",IF($M23=$L23,$Q23,$Q23+($H23-$L23)/($M23-$L23)*($R23-$Q23))) -> 0.51092704 | T23: =IF($P23="","",$P23*($B$14^2+$G23^2)*$B$7) -> 7.2232976 | U23: =IF($T23="","",$T23-$D23) -> 0.82329761 | V23: =IF($S23="","",$S23*($B$14^2+$G23^2)*$B$8) -> 0.21271248 | W23: =IF($V23="","",$V23-$E23) -> -0.016287516 | X23: =IF($B23="","",IFERROR(IF(OR($V23="",ABS($V23)<0.000000001),"",$B$15*$B$16*($C23/86400)*$T23/($V23*1000)),"")) -> 0.1541734 | Y23: =IF($B23="","",IFERROR(ABS($X23),"")) -> 0.1541734 | Z23: =IF($B23="","",IFERROR(IF(OR($F23="",$X23=""),"",$X23-$F23),"")) -> 0.044173402
A24: 3 | B24: =IFERROR(MATCH($B$2&"|"&A24,CatalogData!$G:$G,0),"") -> 309 | C24: =IF($B24="","",INDEX(CatalogData!$C:$C,$B24)) -> 80 | D24: =IF($B24="","",INDEX(CatalogData!$D:$D,$B24)) -> 6.32 | E24: =IF($B24="","",INDEX(CatalogData!$E:$E,$B24)) -> 0.26 | F24: =IF($B24="","",INDEX(CatalogData!$F:$F,$B24)) -> 0.21 | G24: =IF($B24="","",IFERROR($C24/$B$6,"")) -> 0.28571429 | H24: =IF($B24="","",IFERROR(DEGREES(ATAN2($G24,$B$14)),"")) -> 74.054604 | I24: =IF($B24="","",IFERROR(($D24/$B$7)/($B$14^2+$G24^2),"")) -> 1.0378364 | J24: =IF($B24="","",IFERROR(($E24/$B$8)/($B$14^2+$G24^2),"")) -> 0.58916019 | K24: =IF($B24="","",IFERROR(MATCH($H24,SuterWide!$A$2:$A$56,1),"")) -> 15 | L24: =IF($K24="","",INDEX(SuterWide!$A$2:$A$56,$K24)) -> 70 | M24: =IF($K24="","",INDEX(SuterWide!$A$2:$A$56,MIN($K24+1,ROWS(SuterWide!$A$2:$A$56)))) -> 75 | N24: =IF($K24="","",IF($B$12=25,INDEX(SuterWide!$B$2:$B$56,$K24),IF($B$12=147,INDEX(SuterWide!$D$2:$D$56,$K24),INDEX(SuterWide!$F$2:$F$56,$K24)))) -> 1.115 | O24: =IF($K24="","",IF($B$12=25,INDEX(SuterWide!$B$2:$B$56,MIN($K24+1,ROWS(SuterWide!$A$2:$A$56))),IF($B$12=147,INDEX(SuterWide!$D$2:$D$56,MIN($K24+1,ROWS(SuterWide!$A$2:$A$56))),INDEX(SuterWide!$F$2:$F$56,MIN($K24+1,ROWS(SuterWide!$A$2:$A$56)))))) -> 1.188 | P24: =IF($K24="","",IF($M24=$L24,$N24,$N24+($H24-$L24)/($M24-$L24)*($O24-$N24))) -> 1.1741972 | Q24: =IF($K24="","",IF($B$12=25,INDEX(SuterWide!$C$2:$C$56,$K24),IF($B$12=147,INDEX(SuterWide!$E$2:$E$56,$K24),INDEX(SuterWide!$G$2:$G$56,$K24)))) -> 0.6 | R24: =IF($K24="","",IF($B$12=25,INDEX(SuterWide!$C$2:$C$56,MIN($K24+1,ROWS(SuterWide!$A$2:$A$56))),IF($B$12=147,INDEX(SuterWide!$E$2:$E$56,MIN($K24+1,ROWS(SuterWide!$A$2:$A$56))),INDEX(SuterWide!$G$2:$G$56,MIN($K24+1,ROWS(SuterWide!$A$2:$A$56)))))) -> 0.569 | S24: =IF($K24="","",IF($M24=$L24,$Q24,$Q24+($H24-$L24)/($M24-$L24)*($R24-$Q24))) -> 0.57486145 | T24: =IF($P24="","",$P24*($B$14^2+$G24^2)*$B$7) -> 7.1503818 | U24: =IF($T24="","",$T24-$D24) -> 0.8303818 | V24: =IF($S24="","",$S24*($B$14^2+$G24^2)*$B$8) -> 0.25368988 | W24: =IF($V24="","",$V24-$E24) -> -0.0063101205 | X24: =IF($B24="","",IFERROR(IF(OR($V24="",ABS($V24)<0.000000001),"",$B$15*$B$16*($C24/86400)*$T24/($V24*1000)),"")) -> 0.25593107 | Y24: =IF($B24="","",IFERROR(ABS($X24),"")) -> 0.25593107 | Z24: =IF($B24="","",IFERROR(IF(OR($F24="",$X24=""),"",$X24-$F24),"")) -> 0.045931069
A25: 4 | B25: =IFERROR(MATCH($B$2&"|"&A25,CatalogData!$G:$G,0),"") -> 310 | C25: =IF($B25="","",INDEX(CatalogData!$C:$C,$B25)) -> 120 | D25: =IF($B25="","",INDEX(CatalogData!$D:$D,$B25)) -> 6.37 | E25: =IF($B25="","",INDEX(CatalogData!$E:$E,$B25)) -> 0.29 | F25: =IF($B25="","",INDEX(CatalogData!$F:$F,$B25)) -> 0.3 | G25: =IF($B25="","",IFERROR($C25/$B$6,"")) -> 0.42857143 | H25: =IF($B25="","",IFERROR(DEGREES(ATAN2($G25,$B$14)),"")) -> 66.801409 | I25: =IF($B25="","",IFERROR(($D25/$B$7)/($B$14^2+$G25^2),"")) -> 0.95587064 | J25: =IF($B25="","",IFERROR(($E25/$B$8)/($B$14^2+$G25^2),"")) -> 0.6004902 | K25: =IF($B25="","",IFERROR(MATCH($H25,SuterWide!$A$2:$A$56,1),"")) -> 14 | L25: =IF($K25="","",INDEX(SuterWide!$A$2:$A$56,$K25)) -> 65 | M25: =IF($K25="","",INDEX(SuterWide!$A$2:$A$56,MIN($K25+1,ROWS(SuterWide!$A$2:$A$56)))) -> 70 | N25: =IF($K25="","",IF($B$12=25,INDEX(SuterWide!$B$2:$B$56,$K25),IF($B$12=147,INDEX(SuterWide!$D$2:$D$56,$K25),INDEX(SuterWide!$F$2:$F$56,$K25)))) -> 1.007 | O25: =IF($K25="","",IF($B$12=25,INDEX(SuterWide!$B$2:$B$56,MIN($K25+1,ROWS(SuterWide!$A$2:$A$56))),IF($B$12=147,INDEX(SuterWide!$D$2:$D$56,MIN($K25+1,ROWS(SuterWide!$A$2:$A$56))),INDEX(SuterWide!$F$2:$F$56,MIN($K25+1,ROWS(SuterWide!$A$2:$A$56)))))) -> 1.115 | P25: =IF($K25="","",IF($M25=$L25,$N25,$N25+($H25-$L25)/($M25-$L25)*($O25-$N25))) -> 1.0459104 | Q25: =IF($K25="","",IF($B$12=25,INDEX(SuterWide!$C$2:$C$56,$K25),IF($B$12=147,INDEX(SuterWide!$E$2:$E$56,$K25),INDEX(SuterWide!$G$2:$G$56,$K25)))) -> 0.615 | R25: =IF($K25="","",IF($B$12=25,INDEX(SuterWide!$C$2:$C$56,MIN($K25+1,ROWS(SuterWide!$A$2:$A$56))),IF($B$12=147,INDEX(SuterWide!$E$2:$E$56,MIN($K25+1,ROWS(SuterWide!$A$2:$A$56))),INDEX(SuterWide!$G$2:$G$56,MIN($K25+1,ROWS(SuterWide!$A$2:$A$56)))))) -> 0.6 | S25: =IF($K25="","",IF($M25=$L25,$Q25,$Q25+($H25-$L25)/($M25-$L25)*($R25-$Q25))) -> 0.60959577 | T25: =IF($P25="","",$P25*($B$14^2+$G25^2)*$B$7) -> 6.9700326 | U25: =IF($T25="","",$T25-$D25) -> 0.60003259 | V25: =IF($S25="","",$S25*($B$14^2+$G25^2)*$B$8) -> 0.29439744 | W25: =IF($V25="","",$V25-$E25) -> 0.0043974355 | X25: =IF($B25="","",IFERROR(IF(OR($V25="",ABS($V25)<0.000000001),"",$B$15*$B$16*($C25/86400)*$T25/($V25*1000)),"")) -> 0.32246974 | Y25: =IF($B25="","",IFERROR(ABS($X25),"")) -> 0.32246974 | Z25: =IF($B25="","",IFERROR(IF(OR($F25="",$X25=""),"",$X25-$F25),"")) -> 0.022469738
A26: 5 | B26: =IFERROR(MATCH($B$2&"|"&A26,CatalogData!$G:$G,0),"") -> 311 | C26: =IF($B26="","",INDEX(CatalogData!$C:$C,$B26)) -> 160 | D26: =IF($B26="","",INDEX(CatalogData!$D:$D,$B26)) -> 6.42 | E26: =IF($B26="","",INDEX(CatalogData!$E:$E,$B26)) -> 0.321 | F26: =IF($B26="","",INDEX(CatalogData!$F:$F,$B26)) -> 0.37 | G26: =IF($B26="","",IFERROR($C26/$B$6,"")) -> 0.57142857 | H26: =IF($B26="","",IFERROR(DEGREES(ATAN2($G26,$B$14)),"")) -> 60.255119 | I26: =IF($B26="","",IFERROR(($D26/$B$7)/($B$14^2+$G26^2),"")) -> 0.85962563 | J26: =IF($B26="","",IFERROR(($E26/$B$8)/($B$14^2+$G26^2),"")) -> 0.59309955 | K26: =IF($B26="","",IFERROR(MATCH($H26,SuterWide!$A$2:$A$56,1),"")) -> 13 | L26: =IF($K26="","",INDEX(SuterWide!$A$2:$A$56,$K26)) -> 60 | M26: =IF($K26="","",INDEX(SuterWide!$A$2:$A$56,MIN($K26+1,ROWS(SuterWide!$A$2:$A$56)))) -> 65 | N26: =IF($K26="","",IF($B$12=25,INDEX(SuterWide!$B$2:$B$56,$K26),IF($B$12=147,INDEX(SuterWide!$D$2:$D$56,$K26),INDEX(SuterWide!$F$2:$F$56,$K26)))) -> 0.9 | O26: =IF($K26="","",IF($B$12=25,INDEX(SuterWide!$B$2:$B$56,MIN($K26+1,ROWS(SuterWide!$A$2:$A$56))),IF($B$12=147,INDEX(SuterWide!$D$2:$D$56,MIN($K26+1,ROWS(SuterWide!$A$2:$A$56))),INDEX(SuterWide!$F$2:$F$56,MIN($K26+1,ROWS(SuterWide!$A$2:$A$56)))))) -> 1.007 | P26: =IF($K26="","",IF($M26=$L26,$N26,$N26+($H26-$L26)/($M26-$L26)*($O26-$N26))) -> 0.90545954 | Q26: =IF($K26="","",IF($B$12=25,INDEX(SuterWide!$C$2:$C$56,$K26),IF($B$12=147,INDEX(SuterWide!$E$2:$E$56,$K26),INDEX(SuterWide!$G$2:$G$56,$K26)))) -> 0.612 | R26: =IF($K26="","",IF($B$12=25,INDEX(SuterWide!$C$2:$C$56,MIN($K26+1,ROWS(SuterWide!$A$2:$A$56))),IF($B$12=147,INDEX(SuterWide!$E$2:$E$56,MIN($K26+1,ROWS(SuterWide!$A$2:$A$56))),INDEX(SuterWide!$G$2:$G$56,MIN($K26+1,ROWS(SuterWide!$A$2:$A$56)))))) -> 0.615 | S26: =IF($K26="","",IF($M26=$L26,$Q26,$Q26+($H26-$L26)/($M26-$L26)*($R26-$Q26))) -> 0.61215307 | T26: =IF($P26="","",$P26*($B$14^2+$G26^2)*$B$7) -> 6.7623045 | U26: =IF($T26="","",$T26-$D26) -> 0.34230446 | V26: =IF($S26="","",$S26*($B$14^2+$G26^2)*$B$8) -> 0.33131223 | W26: =IF($V26="","",$V26-$E26) -> 0.010312234 | X26: =IF($B26="","",IFERROR(IF(OR($V26="",ABS($V26)<0.000000001),"",$B$15*$B$16*($C26/86400)*$T26/($V26*1000)),"")) -> 0.37066721 | Y26: =IF($B26="","",IFERROR(ABS($X26),"")) -> 0.37066721 | Z26: =IF($B26="","",IFERROR(IF(OR($F26="",$X26=""),"",$X26-$F26),"")) -> 0.00066720542
A27: 6 | B27: =IFERROR(MATCH($B$2&"|"&A27,CatalogData!$G:$G,0),"") -> 312 | C27: =IF($B27="","",INDEX(CatalogData!$C:$C,$B27)) -> 200 | D27: =IF($B27="","",INDEX(CatalogData!$D:$D,$B27)) -> 6.35 | E27: =IF($B27="","",INDEX(CatalogData!$E:$E,$B27)) -> 0.351 | F27: =IF($B27="","",INDEX(CatalogData!$F:$F,$B27)) -> 0.4191 | G27: =IF($B27="","",IFERROR($C27/$B$6,"")) -> 0.71428571 | H27: =IF($B27="","",IFERROR(DEGREES(ATAN2($G27,$B$14)),"")) -> 54.462322 | I27: =IF($B27="","",IFERROR(($D27/$B$7)/($B$14^2+$G27^2),"")) -> 0.74684365 | J27: =IF($B27="","",IFERROR(($E27/$B$8)/($B$14^2+$G27^2),"")) -> 0.56965421 | K27: =IF($B27="","",IFERROR(MATCH($H27,SuterWide!$A$2:$A$56,1),"")) -> 11 | L27: =IF($K27="","",INDEX(SuterWide!$A$2:$A$56,$K27)) -> 50 | M27: =IF($K27="","",INDEX(SuterWide!$A$2:$A$56,MIN($K27+1,ROWS(SuterWide!$A$2:$A$56)))) -> 55 | N27: =IF($K27="","",IF($B$12=25,INDEX(SuterWide!$B$2:$B$56,$K27),IF($B$12=147,INDEX(SuterWide!$D$2:$D$56,$K27),INDEX(SuterWide!$F$2:$F$56,$K27)))) -> 0.655 | O27: =IF($K27="","",IF($B$12=25,INDEX(SuterWide!$B$2:$B$56,MIN($K27+1,ROWS(SuterWide!$A$2:$A$56))),IF($B$12=147,INDEX(SuterWide!$D$2:$D$56,MIN($K27+1,ROWS(SuterWide!$A$2:$A$56))),INDEX(SuterWide!$F$2:$F$56,MIN($K27+1,ROWS(SuterWide!$A$2:$A$56)))))) -> 0.777 | P27: =IF($K27="","",IF($M27=$L27,$N27,$N27+($H27-$L27)/($M27-$L27)*($O27-$N27))) -> 0.76388066 | Q27: =IF($K27="","",IF($B$12=25,INDEX(SuterWide!$C$2:$C$56,$K27),IF($B$12=147,INDEX(SuterWide!$E$2:$E$56,$K27),INDEX(SuterWide!$G$2:$G$56,$K27)))) -> 0.548 | R27: =IF($K27="","",IF($B$12=25,INDEX(SuterWide!$C$2:$C$56,MIN($K27+1,ROWS(SuterWide!$A$2:$A$56))),IF($B$12=147,INDEX(SuterWide!$E$2:$E$56,MIN($K27+1,ROWS(SuterWide!$A$2:$A$56))),INDEX(SuterWide!$G$2:$G$56,MIN($K27+1,ROWS(SuterWide!$A$2:$A$56)))))) -> 0.588 | S27: =IF($K27="","",IF($M27=$L27,$Q27,$Q27+($H27-$L27)/($M27-$L27)*($R27-$Q27))) -> 0.58369858 | T27: =IF($P27="","",$P27*($B$14^2+$G27^2)*$B$7) -> 6.4948564 | U27: =IF($T27="","",$T27-$D27) -> 0.14485635 | V27: =IF($S27="","",$S27*($B$14^2+$G27^2)*$B$8) -> 0.35965362 | W27: =IF($V27="","",$V27-$E27) -> 0.0086536216 | X27: =IF($B27="","",IFERROR(IF(OR($V27="",ABS($V27)<0.000000001),"",$B$15*$B$16*($C27/86400)*$T27/($V27*1000)),"")) -> 0.40994165 | Y27: =IF($B27="","",IFERROR(ABS($X27),"")) -> 0.40994165 | Z27: =IF($B27="","",IFERROR(IF(OR($F27="",$X27=""),"",$X27-$F27),"")) -> -0.0091583534
A28: 7 | B28: =IFERROR(MATCH($B$2&"|"&A28,CatalogData!$G:$G,0),"") -> 313 | C28: =IF($B28="","",INDEX(CatalogData!$C:$C,$B28)) -> 220 | D28: =IF($B28="","",INDEX(CatalogData!$D:$D,$B28)) -> 6.25 | E28: =IF($B28="","",INDEX(CatalogData!$E:$E,$B28)) -> 0.366 | F28: =IF($B28="","",INDEX(CatalogData!$F:$F,$B28)) -> 0.435 | G28: =IF($B28="","",IFERROR($C28/$B$6,"")) -> 0.78571429 | H28: =IF($B28="","",IFERROR(DEGREES(ATAN2($G28,$B$14)),"")) -> 51.842773 | I28: =IF($B28="","",IFERROR(($D28/$B$7)/($B$14^2+$G28^2),"")) -> 0.68638602 | J28: =IF($B28="","",IFERROR(($E28/$B$8)/($B$14^2+$G28^2),"")) -> 0.55464836 | K28: =IF($B28="","",IFERROR(MATCH($H28,SuterWide!$A$2:$A$56,1),"")) -> 11 | L28: =IF($K28="","",INDEX(SuterWide!$A$2:$A$56,$K28)) -> 50 | M28: =IF($K28="","",INDEX(SuterWide!$A$2:$A$56,MIN($K28+1,ROWS(SuterWide!$A$2:$A$56)))) -> 55 | N28: =IF($K28="","",IF($B$12=25,INDEX(SuterWide!$B$2:$B$56,$K28),IF($B$12=147,INDEX(SuterWide!$D$2:$D$56,$K28),INDEX(SuterWide!$F$2:$F$56,$K28)))) -> 0.655 | O28: =IF($K28="","",IF($B$12=25,INDEX(SuterWide!$B$2:$B$56,MIN($K28+1,ROWS(SuterWide!$A$2:$A$56))),IF($B$12=147,INDEX(SuterWide!$D$2:$D$56,MIN($K28+1,ROWS(SuterWide!$A$2:$A$56))),INDEX(SuterWide!$F$2:$F$56,MIN($K28+1,ROWS(SuterWide!$A$2:$A$56)))))) -> 0.777 | P28: =IF($K28="","",IF($M28=$L28,$N28,$N28+($H28-$L28)/($M28-$L28)*($O28-$N28))) -> 0.69996367 | Q28: =IF($K28="","",IF($B$12=25,INDEX(SuterWide!$C$2:$C$56,$K28),IF($B$12=147,INDEX(SuterWide!$E$2:$E$56,$K28),INDEX(SuterWide!$G$2:$G$56,$K28)))) -> 0.548 | R28: =IF($K28="","",IF($B$12=25,INDEX(SuterWide!$C$2:$C$56,MIN($K28+1,ROWS(SuterWide!$A$2:$A$56))),IF($B$12=147,INDEX(SuterWide!$E$2:$E$56,MIN($K28+1,ROWS(SuterWide!$A$2:$A$56))),INDEX(SuterWide!$G$2:$G$56,MIN($K28+1,ROWS(SuterWide!$A$2:$A$56)))))) -> 0.588 | S28: =IF($K28="","",IF($M28=$L28,$Q28,$Q28+($H28-$L28)/($M28-$L28)*($R28-$Q28))) -> 0.56274219 | T28: =IF($P28="","",$P28*($B$14^2+$G28^2)*$B$7) -> 6.3736335 | U28: =IF($T28="","",$T28-$D28) -> 0.12363349 | V28: =IF($S28="","",$S28*($B$14^2+$G28^2)*$B$8) -> 0.37134094 | W28: =IF($V28="","",$V28-$E28) -> 0.0053409364 | X28: =IF($B28="","",IFERROR(IF(OR($V28="",ABS($V28)<0.000000001),"",$B$15*$B$16*($C28/86400)*$T28/($V28*1000)),"")) -> 0.42859181 | Y28: =IF($B28="","",IFERROR(ABS($X28),"")) -> 0.42859181 | Z28: =IF($B28="","",IFERROR(IF(OR($F28="",$X28=""),"",$X28-$F28),"")) -> -0.0064081861
A29: 8 | B29: =IFERROR(MATCH($B$2&"|"&A29,CatalogData!$G:$G,0),"") -> 314 | C29: =IF($B29="","",INDEX(CatalogData!$C:$C,$B29)) -> 240 | D29: =IF($B29="","",INDEX(CatalogData!$D:$D,$B29)) -> 6.1 | E29: =IF($B29="","",INDEX(CatalogData!$E:$E,$B29)) -> 0.38 | F29: =IF($B29="","",INDEX(CatalogData!$F:$F,$B29)) -> 0.4425 | G29: =IF($B29="","",IFERROR($C29/$B$6,"")) -> 0.85714286 | H29: =IF($B29="","",IFERROR(DEGREES(ATAN2($G29,$B$14)),"")) -> 49.398705 | I29: =IF($B29="","",IFERROR(($D29/$B$7)/($B$14^2+$G29^2),"")) -> 0.62459513 | J29: =IF($B29="","",IFERROR(($E29/$B$8)/($B$14^2+$G29^2),"")) -> 0.53690888 | K29: =IF($B29="","",IFERROR(MATCH($H29,SuterWide!$A$2:$A$56,1),"")) -> 10 | L29: =IF($K29="","",INDEX(SuterWide!$A$2:$A$56,$K29)) -> 45 | M29: =IF($K29="","",INDEX(SuterWide!$A$2:$A$56,MIN($K29+1,ROWS(SuterWide!$A$2:$A$56)))) -> 50 | N29: =IF($K29="","",IF($B$12=25,INDEX(SuterWide!$B$2:$B$56,$K29),IF($B$12=147,INDEX(SuterWide!$D$2:$D$56,$K29),INDEX(SuterWide!$F$2:$F$56,$K29)))) -> 0.5 | O29: =IF($K29="","",IF($B$12=25,INDEX(SuterWide!$B$2:$B$56,MIN($K29+1,ROWS(SuterWide!$A$2:$A$56))),IF($B$12=147,INDEX(SuterWide!$D$2:$D$56,MIN($K29+1,ROWS(SuterWide!$A$2:$A$56))),INDEX(SuterWide!$F$2:$F$56,MIN($K29+1,ROWS(SuterWide!$A$2:$A$56)))))) -> 0.655 | P29: =IF($K29="","",IF($M29=$L29,$N29,$N29+($H29-$L29)/($M29-$L29)*($O29-$N29))) -> 0.63635987 | Q29: =IF($K29="","",IF($B$12=25,INDEX(SuterWide!$C$2:$C$56,$K29),IF($B$12=147,INDEX(SuterWide!$E$2:$E$56,$K29),INDEX(SuterWide!$G$2:$G$56,$K29)))) -> 0.5 | R29: =IF($K29="","",IF($B$12=25,INDEX(SuterWide!$C$2:$C$56,MIN($K29+1,ROWS(SuterWide!$A$2:$A$56))),IF($B$12=147,INDEX(SuterWide!$E$2:$E$56,MIN($K29+1,ROWS(SuterWide!$A$2:$A$56))),INDEX(SuterWide!$G$2:$G$56,MIN($K29+1,ROWS(SuterWide!$A$2:$A$56)))))) -> 0.548 | S29: =IF($K29="","",IF($M29=$L29,$Q29,$Q29+($H29-$L29)/($M29-$L29)*($R29-$Q29))) -> 0.54222757 | T29: =IF($P29="","",$P29*($B$14^2+$G29^2)*$B$7) -> 6.2148982 | U29: =IF($T29="","",$T29-$D29) -> 0.11489824 | V29: =IF($S29="","",$S29*($B$14^2+$G29^2)*$B$8) -> 0.38376433 | W29: =IF($V29="","",$V29-$E29) -> 0.0037643301 | X29: =IF($B29="","",IFERROR(IF(OR($V29="",ABS($V29)<0.000000001),"",$B$15*$B$16*($C29/86400)*$T29/($V29*1000)),"")) -> 0.44115133 | Y29: =IF($B29="","",IFERROR(ABS($X29),"")) -> 0.44115133 | Z29: =IF($B29="","",IFERROR(IF(OR($F29="",$X29=""),"",$X29-$F29),"")) -> -0.0013486716
A30: 9 | B30: =IFERROR(MATCH($B$2&"|"&A30,CatalogData!$G:$G,0),"") -> 315 | C30: =IF($B30="","",INDEX(CatalogData!$C:$C,$B30)) -> 280 | D30: =IF($B30="","",INDEX(CatalogData!$D:$D,$B30)) -> 5.63 | E30: =IF($B30="","",INDEX(CatalogData!$E:$E,$B30)) -> 0.408 | F30: =IF($B30="","",INDEX(CatalogData!$F:$F,$B30)) -> 0.44 | G30: =IF($B30="","",IFERROR($C30/$B$6,"")) -> 1 | H30: =IF($B30="","",IFERROR(DEGREES(ATAN2($G30,$B$14)),"")) -> 45 | I30: =IF($B30="","",IFERROR(($D30/$B$7)/($B$14^2+$G30^2),"")) -> 0.5 | J30: =IF($B30="","",IFERROR(($E30/$B$8)/($B$14^2+$G30^2),"")) -> 0.5 | K30: =IF($B30="","",IFERROR(MATCH($H30,SuterWide!$A$2:$A$56,1),"")) -> 10 | L30: =IF($K30="","",INDEX(SuterWide!$A$2:$A$56,$K30)) -> 45 | M30: =IF($K30="","",INDEX(SuterWide!$A$2:$A$56,MIN($K30+1,ROWS(SuterWide!$A$2:$A$56)))) -> 50 | N30: =IF($K30="","",IF($B$12=25,INDEX(SuterWide!$B$2:$B$56,$K30),IF($B$12=147,INDEX(SuterWide!$D$2:$D$56,$K30),INDEX(SuterWide!$F$2:$F$56,$K30)))) -> 0.5 | O30: =IF($K30="","",IF($B$12=25,INDEX(SuterWide!$B$2:$B$56,MIN($K30+1,ROWS(SuterWide!$A$2:$A$56))),IF($B$12=147,INDEX(SuterWide!$D$2:$D$56,MIN($K30+1,ROWS(SuterWide!$A$2:$A$56))),INDEX(SuterWide!$F$2:$F$56,MIN($K30+1,ROWS(SuterWide!$A$2:$A$56)))))) -> 0.655 | P30: =IF($K30="","",IF($M30=$L30,$N30,$N30+($H30-$L30)/($M30-$L30)*($O30-$N30))) -> 0.5 | Q30: =IF($K30="","",IF($B$12=25,INDEX(SuterWide!$C$2:$C$56,$K30),IF($B$12=147,INDEX(SuterWide!$E$2:$E$56,$K30),INDEX(SuterWide!$G$2:$G$56,$K30)))) -> 0.5 | R30: =IF($K30="","",IF($B$12=25,INDEX(SuterWide!$C$2:$C$56,MIN($K30+1,ROWS(SuterWide!$A$2:$A$56))),IF($B$12=147,INDEX(SuterWide!$E$2:$E$56,MIN($K30+1,ROWS(SuterWide!$A$2:$A$56))),INDEX(SuterWide!$G$2:$G$56,MIN($K30+1,ROWS(SuterWide!$A$2:$A$56)))))) -> 0.548 | S30: =IF($K30="","",IF($M30=$L30,$Q30,$Q30+($H30-$L30)/($M30-$L30)*($R30-$Q30))) -> 0.5 | T30: =IF($P30="","",$P30*($B$14^2+$G30^2)*$B$7) -> 5.63 | U30: =IF($T30="","",$T30-$D30) -> 0 | V30: =IF($S30="","",$S30*($B$14^2+$G30^2)*$B$8) -> 0.408 | W30: =IF($V30="","",$V30-$E30) -> 0 | X30: =IF($B30="","",IFERROR(IF(OR($V30="",ABS($V30)<0.000000001),"",$B$15*$B$16*($C30/86400)*$T30/($V30*1000)),"")) -> 0.43854402 | Y30: =IF($B30="","",IFERROR(ABS($X30),"")) -> 0.43854402 | Z30: =IF($B30="","",IFERROR(IF(OR($F30="",$X30=""),"",$X30-$F30),"")) -> -0.0014559771
A31: 10 | B31: =IFERROR(MATCH($B$2&"|"&A31,CatalogData!$G:$G,0),"") -> 316 | C31: =IF($B31="","",INDEX(CatalogData!$C:$C,$B31)) -> 300 | D31: =IF($B31="","",INDEX(CatalogData!$D:$D,$B31)) -> 5.31 | E31: =IF($B31="","",INDEX(CatalogData!$E:$E,$B31)) -> 0.42 | F31: =IF($B31="","",INDEX(CatalogData!$F:$F,$B31)) -> 0.43 | G31: =IF($B31="","",IFERROR($C31/$B$6,"")) -> 1.0714286 | H31: =IF($B31="","",IFERROR(DEGREES(ATAN2($G31,$B$14)),"")) -> 43.025066 | I31: =IF($B31="","",IFERROR(($D31/$B$7)/($B$14^2+$G31^2),"")) -> 0.43909663 | J31: =IF($B31="","",IFERROR(($E31/$B$8)/($B$14^2+$G31^2),"")) -> 0.47925108 | K31: =IF($B31="","",IFERROR(MATCH($H31,SuterWide!$A$2:$A$56,1),"")) -> 9 | L31: =IF($K31="","",INDEX(SuterWide!$A$2:$A$56,$K31)) -> 40 | M31: =IF($K31="","",INDEX(SuterWide!$A$2:$A$56,MIN($K31+1,ROWS(SuterWide!$A$2:$A$56)))) -> 45 | N31: =IF($K31="","",IF($B$12=25,INDEX(SuterWide!$B$2:$B$56,$K31),IF($B$12=147,INDEX(SuterWide!$D$2:$D$56,$K31),INDEX(SuterWide!$F$2:$F$56,$K31)))) -> 0.345 | O31: =IF($K31="","",IF($B$12=25,INDEX(SuterWide!$B$2:$B$56,MIN($K31+1,ROWS(SuterWide!$A$2:$A$56))),IF($B$12=147,INDEX(SuterWide!$D$2:$D$56,MIN($K31+1,ROWS(SuterWide!$A$2:$A$56))),INDEX(SuterWide!$F$2:$F$56,MIN($K31+1,ROWS(SuterWide!$A$2:$A$56)))))) -> 0.5 | P31: =IF($K31="","",IF($M31=$L31,$N31,$N31+($H31-$L31)/($M31-$L31)*($O31-$N31))) -> 0.43877705 | Q31: =IF($K31="","",IF($B$12=25,INDEX(SuterWide!$C$2:$C$56,$K31),IF($B$12=147,INDEX(SuterWide!$E$2:$E$56,$K31),INDEX(SuterWide!$G$2:$G$56,$K31)))) -> 0.425 | R31: =IF($K31="","",IF($B$12=25,INDEX(SuterWide!$C$2:$C$56,MIN($K31+1,ROWS(SuterWide!$A$2:$A$56))),IF($B$12=147,INDEX(SuterWide!$E$2:$E$56,MIN($K31+1,ROWS(SuterWide!$A$2:$A$56))),INDEX(SuterWide!$G$2:$G$56,MIN($K31+1,ROWS(SuterWide!$A$2:$A$56)))))) -> 0.5 | S31: =IF($K31="","",IF($M31=$L31,$Q31,$Q31+($H31-$L31)/($M31-$L31)*($R31-$Q31))) -> 0.47037599 | T31: =IF($P31="","",$P31*($B$14^2+$G31^2)*$B$7) -> 5.3061353 | U31: =IF($T31="","",$T31-$D31) -> -0.0038647095 | V31: =IF($S31="","",$S31*($B$14^2+$G31^2)*$B$8) -> 0.41222216 | W31: =IF($V31="","",$V31-$E31) -> -0.0077778417 | X31: =IF($B31="","",IFERROR(IF(OR($V31="",ABS($V31)<0.000000001),"",$B$15*$B$16*($C31/86400)*$T31/($V31*1000)),"")) -> 0.43830374 | Y31: =IF($B31="","",IFERROR(ABS($X31),"")) -> 0.43830374 | Z31: =IF($B31="","",IFERROR(IF(OR($F31="",$X31=""),"",$X31-$F31),"")) -> 0.0083037375
A32: 11 | B32: =IFERROR(MATCH($B$2&"|"&A32,CatalogData!$G:$G,0),"") -> 317 | C32: =IF($B32="","",INDEX(CatalogData!$C:$C,$B32)) -> 320 | D32: =IF($B32="","",INDEX(CatalogData!$D:$D,$B32)) -> 4.93 | E32: =IF($B32="","",INDEX(CatalogData!$E:$E,$B32)) -> 0.433 | F32: =IF($B32="","",INDEX(CatalogData!$F:$F,$B32)) -> 0.41 | G32: =IF($B32="","",IFERROR($C32/$B$6,"")) -> 1.1428571 | H32: =IF($B32="","",IFERROR(DEGREES(ATAN2($G32,$B$14)),"")) -> 41.185925 | I32: =IF($B32="","",IFERROR(($D32/$B$7)/($B$14^2+$G32^2),"")) -> 0.37971361 | J32: =IF($B32="","",IFERROR(($E32/$B$8)/($B$14^2+$G32^2),"")) -> 0.46019868 | K32: =IF($B32="","",IFERROR(MATCH($H32,SuterWide!$A$2:$A$56,1),"")) -> 9 | L32: =IF($K32="","",INDEX(SuterWide!$A$2:$A$56,$K32)) -> 40 | M32: =IF($K32="","",INDEX(SuterWide!$A$2:$A$56,MIN($K32+1,ROWS(SuterWide!$A$2:$A$56)))) -> 45 | N32: =IF($K32="","",IF($B$12=25,INDEX(SuterWide!$B$2:$B$56,$K32),IF($B$12=147,INDEX(SuterWide!$D$2:$D$56,$K32),INDEX(SuterWide!$F$2:$F$56,$K32)))) -> 0.345 | O32: =IF($K32="","",IF($B$12=25,INDEX(SuterWide!$B$2:$B$56,MIN($K32+1,ROWS(SuterWide!$A$2:$A$56))),IF($B$12=147,INDEX(SuterWide!$D$2:$D$56,MIN($K32+1,ROWS(SuterWide!$A$2:$A$56))),INDEX(SuterWide!$F$2:$F$56,MIN($K32+1,ROWS(SuterWide!$A$2:$A$56)))))) -> 0.5 | P32: =IF($K32="","",IF($M32=$L32,$N32,$N32+($H32-$L32)/($M32-$L32)*($O32-$N32))) -> 0.38176368 | Q32: =IF($K32="","",IF($B$12=25,INDEX(SuterWide!$C$2:$C$56,$K32),IF($B$12=147,INDEX(SuterWide!$E$2:$E$56,$K32),INDEX(SuterWide!$G$2:$G$56,$K32)))) -> 0.425 | R32: =IF($K32="","",IF($B$12=25,INDEX(SuterWide!$C$2:$C$56,MIN($K32+1,ROWS(SuterWide!$A$2:$A$56))),IF($B$12=147,INDEX(SuterWide!$E$2:$E$56,MIN($K32+1,ROWS(SuterWide!$A$2:$A$56))),INDEX(SuterWide!$G$2:$G$56,MIN($K32+1,ROWS(SuterWide!$A$2:$A$56)))))) -> 0.5 | S32: =IF($K32="","",IF($M32=$L32,$Q32,$Q32+($H32-$L32)/($M32-$L32)*($R32-$Q32))) -> 0.44278888 | T32: =IF($P32="","",$P32*($B$14^2+$G32^2)*$B$7) -> 4.9566171 | U32: =IF($T32="","",$T32-$D32) -> 0.026617054 | V32: =IF($S32="","",$S32*($B$14^2+$G32^2)*$B$8) -> 0.41661915 | W32: =IF($V32="","",$V32-$E32) -> -0.016380849 | X32: =IF($B32="","",IFERROR(IF(OR($V32="",ABS($V32)<0.000000001),"",$B$15*$B$16*($C32/86400)*$T32/($V32*1000)),"")) -> 0.43211869 | Y32: =IF($B32="","",IFERROR(ABS($X32),"")) -> 0.43211869 | Z32: =IF($B32="","",IFERROR(IF(OR($F32="",$X32=""),"",$X32-$F32),"")) -> 0.022118688
A33: 12 | B33: =IFERROR(MATCH($B$2&"|"&A33,CatalogData!$G:$G,0),"") -> 318 | C33: =IF($B33="","",INDEX(CatalogData!$C:$C,$B33)) -> 350 | D33: =IF($B33="","",INDEX(CatalogData!$D:$D,$B33)) -> 4.26 | E33: =IF($B33="","",INDEX(CatalogData!$E:$E,$B33)) -> 0.45 | F33: =IF($B33="","",INDEX(CatalogData!$F:$F,$B33)) -> 0.37 | G33: =IF($B33="","",IFERROR($C33/$B$6,"")) -> 1.25 | H33: =IF($B33="","",IFERROR(DEGREES(ATAN2($G33,$B$14)),"")) -> 38.659808 | I33: =IF($B33="","",IFERROR(($D33/$B$7)/($B$14^2+$G33^2),"")) -> 0.29528224 | J33: =IF($B33="","",IFERROR(($E33/$B$8)/($B$14^2+$G33^2),"")) -> 0.43041607 | K33: =IF($B33="","",IFERROR(MATCH($H33,SuterWide!$A$2:$A$56,1),"")) -> 8 | L33: =IF($K33="","",INDEX(SuterWide!$A$2:$A$56,$K33)) -> 35 | M33: =IF($K33="","",INDEX(SuterWide!$A$2:$A$56,MIN($K33+1,ROWS(SuterWide!$A$2:$A$56)))) -> 40 | N33: =IF($K33="","",IF($B$12=25,INDEX(SuterWide!$B$2:$B$56,$K33),IF($B$12=147,INDEX(SuterWide!$D$2:$D$56,$K33),INDEX(SuterWide!$F$2:$F$56,$K33)))) -> 0.2 | O33: =IF($K33="","",IF($B$12=25,INDEX(SuterWide!$B$2:$B$56,MIN($K33+1,ROWS(SuterWide!$A$2:$A$56))),IF($B$12=147,INDEX(SuterWide!$D$2:$D$56,MIN($K33+1,ROWS(SuterWide!$A$2:$A$56))),INDEX(SuterWide!$F$2:$F$56,MIN($K33+1,ROWS(SuterWide!$A$2:$A$56)))))) -> 0.345 | P33: =IF($K33="","",IF($M33=$L33,$N33,$N33+($H33-$L33)/($M33-$L33)*($O33-$N33))) -> 0.30613444 | Q33: =IF($K33="","",IF($B$12=25,INDEX(SuterWide!$C$2:$C$56,$K33),IF($B$12=147,INDEX(SuterWide!$E$2:$E$56,$K33),INDEX(SuterWide!$G$2:$G$56,$K33)))) -> 0.32 | R33: =IF($K33="","",IF($B$12=25,INDEX(SuterWide!$C$2:$C$56,MIN($K33+1,ROWS(SuterWide!$A$2:$A$56))),IF($B$12=147,INDEX(SuterWide!$E$2:$E$56,MIN($K33+1,ROWS(SuterWide!$A$2:$A$56))),INDEX(SuterWide!$G$2:$G$56,MIN($K33+1,ROWS(SuterWide!$A$2:$A$56)))))) -> 0.425 | S33: =IF($K33="","",IF($M33=$L33,$Q33,$Q33+($H33-$L33)/($M33-$L33)*($R33-$Q33))) -> 0.39685597 | T33: =IF($P33="","",$P33*($B$14^2+$G33^2)*$B$7) -> 4.4165633 | U33: =IF($T33="","",$T33-$D33) -> 0.15656329 | V33: =IF($S33="","",$S33*($B$14^2+$G33^2)*$B$8) -> 0.41491292 | W33: =IF($V33="","",$V33-$E33) -> -0.03508708 | X33: =IF($B33="","",IFERROR(IF(OR($V33="",ABS($V33)<0.000000001),"",$B$15*$B$16*($C33/86400)*$T33/($V33*1000)),"")) -> 0.42286572 | Y33: =IF($B33="","",IFERROR(ABS($X33),"")) -> 0.42286572 | Z33: =IF($B33="","",IFERROR(IF(OR($F33="",$X33=""),"",$X33-$F33),"")) -> 0.052865717
... A61: 40 | B61: =IFERROR(MATCH($B$2&"|"&A61,CatalogData!$G:$G,0),"") | C61: =IF($B61="","",INDEX(CatalogData!$C:$C,$B61)) | D61: =IF($B61="","",INDEX(CatalogData!$D:$D,$B61)) | E61: =IF($B61="","",INDEX(CatalogData!$E:$E,$B61)) | F61: =IF($B61="","",INDEX(CatalogData!$F:$F,$B61)) | G61: =IF($B61="","",IFERROR($C61/$B$6,"")) | H61: =IF($B61="","",IFERROR(DEGREES(ATAN2($G61,$B$14)),"")) | I61: =IF($B61="","",IFERROR(($D61/$B$7)/($B$14^2+$G61^2),"")) | J61: =IF($B61="","",IFERROR(($E61/$B$8)/($B$14^2+$G61^2),"")) | K61: =IF($B61="","",IFERROR(MATCH($H61,SuterWide!$A$2:$A$56,1),"")) | L61: =IF($K61="","",INDEX(SuterWide!$A$2:$A$56,$K61)) | M61: =IF($K61="","",INDEX(SuterWide!$A$2:$A$56,MIN($K61+1,ROWS(SuterWide!$A$2:$A$56)))) | N61: =IF($K61="","",IF($B$12=25,INDEX(SuterWide!$B$2:$B$56,$K61),IF($B$12=147,INDEX(SuterWide!$D$2:$D$56,$K61),INDEX(SuterWide!$F$2:$F$56,$K61)))) | O61: =IF($K61="","",IF($B$12=25,INDEX(SuterWide!$B$2:$B$56,MIN($K61+1,ROWS(SuterWide!$A$2:$A$56))),IF($B$12=147,INDEX(SuterWide!$D$2:$D$56,MIN($K61+1,ROWS(SuterWide!$A$2:$A$56))),INDEX(SuterWide!$F$2:$F$56,MIN($K61+1,ROWS(SuterWide!$A$2:$A$56)))))) | P61: =IF($K61="","",IF($M61=$L61,$N61,$N61+($H61-$L61)/($M61-$L61)*($O61-$N61))) | Q61: =IF($K61="","",IF($B$12=25,INDEX(SuterWide!$C$2:$C$56,$K61),IF($B$12=147,INDEX(SuterWide!$E$2:$E$56,$K61),INDEX(SuterWide!$G$2:$G$56,$K61)))) | R61: =IF($K61="","",IF($B$12=25,INDEX(SuterWide!$C$2:$C$56,MIN($K61+1,ROWS(SuterWide!$A$2:$A$56))),IF($B$12=147,INDEX(SuterWide!$E$2:$E$56,MIN($K61+1,ROWS(SuterWide!$A$2:$A$56))),INDEX(SuterWide!$G$2:$G$56,MIN($K61+1,ROWS(SuterWide!$A$2:$A$56)))))) | S61: =IF($K61="","",IF($M61=$L61,$Q61,$Q61+($H61-$L61)/($M61-$L61)*($R61-$Q61))) | T61: =IF($P61="","",$P61*($B$14^2+$G61^2)*$B$7) | U61: =IF($T61="","",$T61-$D61) | V61: =IF($S61="","",$S61*($B$14^2+$G61^2)*$B$8) | W61: =IF($V61="","",$V61-$E61) | X61: =IF($B61="","",IFERROR(IF(OR($V61="",ABS($V61)<0.000000001),"",$B$15*$B$16*($C61/86400)*$T61/($V61*1000)),"")) | Y61: =IF($B61="","",IFERROR(ABS($X61),"")) | Z61: =IF($B61="","",IFERROR(IF(OR($F61="",$X61=""),"",$X61-$F61),""))

Sheet Unifloc
A1: ESP_q_nom | B1: 80 | C1: =[1]!ESP_name(B4) -> ЭЦН5А-280 | G1: gamma_gas | H1: 0.6 | L1: qliq_m3day | M1: =H11 -> 1
A2: ESP_head_nom | B2: 1500 | G2: gamma_oil | H2: 0.86 | L2: esp_json | M2: =esp_json_1 -> {"q_nom_sm3day":280,"head_nom_m":5.63,"freq_nom_Hz":50,"name":"ESP-280-6","ESP_ID":750,"num_stages":1,"gas_correct_model":1,"gas_correct_stage_by_stage":0,"calibr_head":1,"calibr_power":1,"calibr_rate":1,"dnum_stages_integrate":1}
A3: size | B3: 5A | C3: 2 | G3: gamma_wat | H3: 1 | L3: freq_Hz | M3: =B5 -> 50
A4: ESP_ID | B4: =Проверка!B2 -> 750 | C4: 2A | G4: rsb_m3m3 | H4: 120 | L4: mu_cSt | M4: 1
A5: freq_nom | B5: =[1]!esp_freq_nom(B4) -> 50 | C5: 3 | G5: pb_atma | H5: 130 | L5: esp nom power_W | M5: =[1]!ESP_power_W(M1, M2, M3, M4) -> 199.73781
A6: num_stages | B6: 1 | C6: 4 | G6: t_res_C | H6: 15
A7: calibr_head | B7: 1 | C7: 5 | G7: bob_m3m3 | H7: 1.2
A8: calibr_rate | B8: 1 | C8: 5A | G8: muob_cP | H8: 1
A9: calibr_power | B9: 1 | C9: 6 | G9: pvt_corr_set | H9: 0
A10: gas_correct_model | B10: 1 | C10: 6A | G10: PVT | H10: =[1]!encode_PVT(H1,H2,H3,H4,H5,H6,H7,H8,H9) -> {"gamma_gas":0.6,"gamma_oil":0.86,"gamma_wat":1,"rsb_m3m3":120,"pb_atma":130,"t_res_C":15,"bob_m3m3":1.2,"muob_cP":1,"PVT_corr_set":0}
A11: gas_correct_stage_by_stage | B11: 0 | C11: 7 | G11: q_liq_sm3day | H11: 1
A12: dnum_stages_integrate | B12: 1 | C12: 7A | G12: fw_perc | H12: 100
A13: encode_esp_pump | B13: =[1]!encode_ESP_pump(,, B5, B4, B6, B7, B8, B9, B10, B11, B12) -> {"q_nom_sm3day":280,"head_nom_m":5.63,"freq_nom_Hz":50,"name":"ESP-280-6","ESP_ID":750,"num_stages":1,"gas_correct_model":1,"gas_correct_stage_by_stage":0,"calibr_head":1,"calibr_power":1,"calibr_rate":1,"dnum_stages_integrate":1} | G13: rp_m3m3 | H13: 120
G14: q_gas_free_sm3day | H14: 0
G15: feed | H15: =[1]!encode_feed(H11,H12,H13,H14,H10) -> {"gamma_gas":0.6,"gamma_oil":0.86,"gamma_wat":1,"rsb_m3m3":120,"pb_atma":130,"t_res_C":15,"bob_m3m3":1.2,"muob_cP":1,"PVT_corr_set":0,"q_liq_sm3day":1,"fw_perc":100,"rp_m3m3":120}
A16: p_atma | B16: 100
A17: t_intake_C | B17: 15
A18: t_dis_C | B18: -1 | G18: =[1]!PVT_rho_oil_kgm3(B30,D30,PVT_json) -> 811.24859
A19: feed | B19: =feed_json -> {"gamma_gas":0.6,"gamma_oil":0.86,"gamma_wat":1,"rsb_m3m3":120,"pb_atma":130,"t_res_C":15,"bob_m3m3":1.2,"muob_cP":1,"PVT_corr_set":0,"q_liq_sm3day":1,"fw_perc":100,"rp_m3m3":120} | G19: =[1]!PVT_rho_wat_kgm3(B30,D30,PVT_json) -> 1001.5497
A20: json_ESP_pump | B20: =esp_json_1 -> {"q_nom_sm3day":280,"head_nom_m":5.63,"freq_nom_Hz":50,"name":"ESP-280-6","ESP_ID":750,"num_stages":1,"gas_correct_model":1,"gas_correct_stage_by_stage":0,"calibr_head":1,"calibr_power":1,"calibr_rate":1,"dnum_stages_integrate":1}
A21: freq_Hz | B21: =B5 -> 50
A22: calc_along_flow | B22: 1
A23: param | B23: {"show_array":1}
A24: h_mes_top | B24: 1000
A25: q_liq_sm3day
A26: fw_perc | D26: q_min | E26: 1
A27: rp_m3m3 | D27: q_max | E27: =[1]!ESP_rate_max_sm3day(B20,B21,1) -> 500
A28: q_gas_free_sm3day | D28: q_list | E28: =[1]!encode_linspace(E26,E27,20) -> [1,25.95,50.9,75.85,100.8,125.75,150.7,175.65,200.6,225.55,250.5,275.45,300.4,325.35,350.3,375.25,400.2,425.15,450.1,475.05,500]
A29: q_liq_sm3day | B29: p_dis_atma | C29: p_int_atma | D29: t_int_C | E29: p_dis_atma | F29: t_dis_C | G29: head_m | H29: eff_ESP_d, % | I29: power_fluid_W | J29: power_ESP_W | K29: gas_correction | L29: log
A30: {=[1]!decode_json(E28)} -> 1 | B30: {=[1]!ESP_p_atma($B$16,$B$17,$B$18,$B$19,$B$20,$B$21,$B$22,$B$23,$B$24,$A$30,$B$26,$B$27,$B$28)} -> 100.65336 | C30: 100 | D30: 15 | E30: 100.65336 | F30: 19.123012 | G30: 6.7379777 | H30: 0.38243654 | I30: 0.76504122 | J30: 200.04397 | K30: 1 | L30: ["set show_log=1 in param to show calc log"]
A31: 25.95 | B31: {=[1]!ESP_p_atma($B$16,$B$17,$B$18,$B$19,$B$20,$B$21,$B$22,$B$23,$B$24,$A$31,$B$26,$B$27,$B$28)} -> 100.62955 | C31: 100 | D31: 15 | E31: 100.62955 | F31: 15.159079 | G31: 6.4924835 | H31: 8.7487351 | I31: 19.129494 | J31: 218.6544 | K31: 1 | L31: ["set show_log=1 in param to show calc log"]
A32: 50.9 | B32: {=[1]!ESP_p_atma($B$16,$B$17,$B$18,$B$19,$B$20,$B$21,$B$22,$B$23,$B$24,$A$32,$B$26,$B$27,$B$28)} -> 100.61593 | C32: 100 | D32: 15 | E32: 100.61593 | F32: 15.081701 | G32: 6.351981 | H32: 15.443321 | I32: 36.709819 | J32: 237.70676 | K32: 1 | L32: ["set show_log=1 in param to show calc log"]
A33: 75.85 | B33: {=[1]!ESP_p_atma($B$16,$B$17,$B$18,$B$19,$B$20,$B$21,$B$22,$B$23,$B$24,$A$33,$B$26,$B$27,$B$28)} -> 100.61245 | C33: 100 | D33: 15 | E33: 100.61245 | F33: 15.055299 | G33: 6.316095 | H33: 21.155031 | I33: 54.395066 | J33: 257.1259 | K33: 1 | L33: ["set show_log=1 in param to show calc log"]
A34: 100.8 | B34: {=[1]!ESP_p_atma($B$16,$B$17,$B$18,$B$19,$B$20,$B$21,$B$22,$B$23,$B$24,$A$34,$B$26,$B$27,$B$28)} -> 100.61533 | C34: 100 | D34: 15 | E34: 100.61533 | F34: 15.041723 | G34: 6.3458065 | H34: 26.323592 | I34: 72.627755 | J34: 275.90366 | K34: 1 | L34: ["set show_log=1 in param to show calc log"]
A35: 125.75 | B35: {=[1]!ESP_p_atma($B$16,$B$17,$B$18,$B$19,$B$20,$B$21,$B$22,$B$23,$B$24,$A$35,$B$26,$B$27,$B$28)} -> 100.61835 | C35: 100 | D35: 15 | E35: 100.61835 | F35: 15.033511 | G35: 6.376946 | H35: 30.892988 | I35: 91.049172 | J35: 294.72439 | K35: 1 | L35: ["set show_log=1 in param to show calc log"]
A36: 150.7 | B36: {=[1]!ESP_p_atma($B$16,$B$17,$B$18,$B$19,$B$20,$B$21,$B$22,$B$23,$B$24,$A$36,$B$26,$B$27,$B$28)} -> 100.62137 | C36: 100 | D36: 15 | E36: 100.62137 | F36: 15.028085 | G36: 6.4080856 | H36: 34.895829 | I36: 109.64702 | J36: 314.21239 | K36: 1 | L36: ["set show_log=1 in param to show calc log"]
A37: 175.65 | B37: {=[1]!ESP_p_atma($B$16,$B$17,$B$18,$B$19,$B$20,$B$21,$B$22,$B$23,$B$24,$A$37,$B$26,$B$27,$B$28)} -> 100.62223 | C37: 100 | D37: 15 | E37: 100.62223 | F37: 15.024155 | G37: 6.4170168 | H37: 38.426552 | I37: 127.97838 | J37: 333.04673 | K37: 1 | L37: ["set show_log=1 in param to show calc log"]
A38: 200.6 | B38: {=[1]!ESP_p_atma($B$16,$B$17,$B$18,$B$19,$B$20,$B$21,$B$22,$B$23,$B$24,$A$38,$B$26,$B$27,$B$28)} -> 100.61563 | C38: 100 | D38: 15 | E38: 100.61563 | F38: 15.021365 | G38: 6.3489639 | H38: 41.109616 | I38: 144.60691 | J38: 351.75934 | K38: 1 | L38: ["set show_log=1 in param to show calc log"]
A39: 225.55 | B39: {=[1]!ESP_p_atma($B$16,$B$17,$B$18,$B$19,$B$20,$B$21,$B$22,$B$23,$B$24,$A$39,$B$26,$B$27,$B$28)} -> 100.6028 | C39: 100 | D39: 15 | E39: 100.6028 | F39: 15.019362 | G39: 6.2165849 | H39: 42.994887 | I39: 159.20253 | J39: 370.28247 | K39: 1 | L39: ["set show_log=1 in param to show calc log"]
A40: 250.5 | B40: {=[1]!ESP_p_atma($B$16,$B$17,$B$18,$B$19,$B$20,$B$21,$B$22,$B$23,$B$24,$A$40,$B$26,$B$27,$B$28)} -> 100.5819 | C40: 100 | D40: 15 | E40: 100.5819 | F40: 15.017922 | G40: 6.0010164 | H40: 44.026962 | I40: 170.68203 | J40: 387.67616 | K40: 1 | L40: ["set show_log=1 in param to show calc log"]
...

Sheet Pumps
A1: pump_id | B1: name | C1: manufacturer | D1: series | E1: Q_star_sm3day | F1: H_star_m | G1: N_star_kw | H1: freq_Hz | I1: slip_nom_rpm
A2: 3360 | B2: ЭЦН5А-360@50 Hz | C2: borets | D2: 5А | E2: 360 | F2: 4.6039275 | G2: 0.33672051 | H2: 50 | I2: 2910
A3: 1012 | B3: ЭЦН2А-30Э | C3: Generic | D3: 2А | E3: 30 | F3: 2.7 | G3: 0.019 | H3: 50 | I3: 2910
A4: 1016 | B4: ЭЦН2А-50Э | C4: Generic | D4: 2А | E4: 50 | F4: 2.8 | G4: 0.025 | H4: 50 | I4: 2910
A5: 871 | B5: ЭЦН3-90 | C5: Generic | D5: 3 | E5: 90 | F5: 19.67 | G5: 0.371 | H5: 108 | I5: 6450
A6: 1002 | B6: ЭЦН4-20 | C6: Generic | D6: 4 | E6: 20 | F6: 4.5 | G6: 0.03 | H6: 50 | I6: 2820
A7: 878 | B7: ЭЦН4-200 | C7: Generic | D7: 4 | E7: 200 | F7: 3.6 | G7: 0.154 | H7: 50 | I7: 2820
A8: 736 | B8: ЭЦН4-30 | C8: Generic | D8: 4 | E8: 30 | F8: 4.1 | G8: 0.035 | H8: 50 | I8: 2820
A9: 1007 | B9: ЭЦН5-100 | C9: Generic | D9: 5 | E9: 100 | F9: 5.8 | G9: 0.11 | H9: 50 | I9: 2910
A10: 737 | B10: ЭЦН5-125 | C10: Generic | D10: 5 | E10: 125 | F10: 5.8 | G10: 0.148 | H10: 50 | I10: 2910
A11: 799 | B11: ЭЦН5-125 | C11: Generic | D11: 5 | E11: 150 | F11: 8.2708763 | G11: 0.2564655 | H11: 60 | I11: 3500
A12: 738 | B12: ЭЦН5-15 | C12: Generic | D12: 5 | E12: 15 | F12: 5.5 | G12: 0.031 | H12: 50 | I12: 2910
A13: 1003 | B13: ЭЦН5-20 | C13: Generic | D13: 5 | E13: 20 | F13: 4.7 | G13: 0.032 | H13: 50 | I13: 2910
... A57: 2089 | B57: ЭЦН5А-80@50Гц | C57: novomet | D57: 5А | E57: 80 | F57: 6.5349199 | G57: 0.10625763 | H57: 50 | I57: 2910

Sheet CatalogData
A1: pump_id | B1: point_index | C1: Q_sm3day | D1: H_m | E1: N_kw | F1: eta_db | G1: lookup_key
A2: 3360 | B2: 0 | C2: 0 | D2: 6.2380249 | E2: 0.19965702 | F2: 0 | G2: 3360|1
A3: 3360 | B3: 1 | C3: 52.917 | D3: 6.19059 | E3: 0.21595992 | F3: 0.17222605 | G3: 3360|2
A4: 3360 | B4: 2 | C4: 105.833 | D4: 6.1580465 | E4: 0.24174622 | F4: 0.306098 | G4: 3360|3
A5: 3360 | B5: 3 | C5: 158.75 | D5: 6.0361399 | E5: 0.27256297 | F5: 0.39917956 | G5: 3360|4
A6: 3360 | B6: 4 | C6: 211.667 | D6: 5.8477013 | E6: 0.30367515 | F6: 0.46279034 | G6: 3360|5
A7: 3360 | B7: 5 | C7: 264.583 | D7: 5.5942533 | E7: 0.32896187 | F7: 0.51087357 | G7: 3360|6
A8: 3360 | B8: 6 | C8: 317.5 | D8: 5.1874511 | E8: 0.34144418 | F8: 0.54768887 | G8: 3360|7
A9: 3360 | B9: 7 | C9: 370.417 | D9: 4.4609024 | E9: 0.33556271 | F9: 0.55911475 | G9: 3360|8
A10: 3360 | B10: 8 | C10: 423.333 | D10: 3.262266 | E10: 0.31114203 | F10: 0.50398254 | G10: 3360|9
A11: 3360 | B11: 9 | C11: 476.25 | D11: 1.6257491 | E11: 0.27905595 | F11: 0.31498663 | G11: 3360|10
A12: 3360 | B12: 10 | C12: 529.167 | D12: 0 | E12: 0.26859631 | F12: 0 | G12: 3360|11
A13: 1012 | B13: 0 | C13: 0 | D13: 3.3 | E13: 0.018 | F13: 0 | G13: 1012|1
... A655: 2089 | B655: 10 | C655: 136 | D655: 0 | E655: 0.12140566 | F655: 0 | G655: 2089|11

Sheet SuterWide
A1: theta_deg | B1: Wh_25 | C1: Wm_25 | D1: Wh_147 | E1: Wm_147 | F1: Wh_261 | G1: Wm_261
A2: 0 | B2: -0.53 | C2: -0.35 | D2: -1.56 | E2: -1.56 | F2: -1 | G2: -0.56
A3: 5 | B3: -0.476 | C3: -0.474 | D3: -1.29 | E3: -1.2 | F3: -0.948 | G3: -0.6
A4: 10 | B4: -0.392 | C4: -0.18 | D4: -1.035 | E4: -0.895 | F4: -0.892 | G4: -0.605
A5: 15 | B5: -0.291 | C5: -0.062 | D5: -0.795 | E5: -0.6 | F5: -0.82 | G5: -0.58
A6: 20 | B6: -0.15 | C6: 0.037 | D6: -0.54 | E6: -0.355 | F6: -0.665 | G6: -0.503
A7: 25 | B7: -0.037 | C7: 0.135 | D7: -0.308 | E7: -0.135 | F7: -0.475 | G7: -0.355
A8: 30 | B8: 0.075 | C8: 0.228 | D8: -0.032 | E8: 0.06 | F8: -0.275 | G8: -0.16
A9: 35 | B9: 0.2 | C9: 0.32 | D9: 0.122 | E9: 0.235 | F9: -0.055 | G9: 0.07
A10: 40 | B10: 0.345 | C10: 0.425 | D10: 0.31 | E10: 0.38 | F10: 0.2 | G10: 0.32
A11: 45 | B11: 0.5 | C11: 0.5 | D11: 0.5 | E11: 0.5 | F11: 0.5 | G11: 0.5
A12: 50 | B12: 0.655 | C12: 0.548 | D12: 0.635 | E12: 0.58 | F12: 0.785 | G12: 0.62
A13: 55 | B13: 0.777 | C13: 0.588 | D13: 0.745 | E13: 0.645 | F13: 1.035 | G13: 0.708
... A56: 270 | B56: 0.63 | C56: -0.63 | D56: -0.67 | E56: -1.5 | F56: -2.2 | G56: -2.2
